<h1>Projeto de blog pessoal utilizando django</h1>
<h3>Consertar erro:</h3>
<ul>
    <li>Step 9/12 : RUN python -m venv /venv &&   /venv/bin/pip install -r /djangoapp/requirements.txt &&   adduser --disabled-password --no-create-home duser &&   mkdir -p /data/web/static &&   mkdir -p /data/web/media &&   chown -R duser:duser /venv &&   chown -R duser:duser /data/web/static &&   chown -R duser:duser /data/web/media &&   chmod -R 755 /data/web/static &&   chmod -R 755 /data/web/media &&   chmod -R +x /scripts
 ---> Running in d05f5297956a
WARNING: Retrying (Retry(total=4, connect=None, read=None, redirect=None, status=None)) after connection broken by 'ConnectTimeoutError(<pip._vendor.urllib3.connection.HTTPSConnection object at 0x7f2e3644df10>, 'Connection to pypi.org timed out. (connect timeout=15)')': /simple/django/</li>
</ul>
